<?xml version="1.0" encoding="utf-8"?>
<!-- This URDF was automatically created by SolidWorks to URDF Exporter! Originally created by Stephen Brawner (brawner@gmail.com) 
     Commit Version: 1.5.1-0-g916b5db  Build Version: 1.5.7152.31018
     For more information, please see http://wiki.ros.org/sw_urdf_exporter -->
<robot
  name="segway_e1_description">
  <link name="base_link"/>
  <link
    name="Chassis body">
    <inertial>
      <origin
        xyz="-0.033482 0.22487 0.0057368"
        rpy="0 0 0" />
      <mass
        value="1.5192" />
      <inertia
        ixx="0.048829"
        ixy="1.5025E-05"
        ixz="1.729E-06"
        iyy="0.0069994"
        iyz="-0.002399"
        izz="0.052057" />
    </inertial>
    <visual>
      <origin
        xyz="0 0 0"
        rpy="0 0 0" />
      <geometry>
        <mesh
          filename="package://segway_e1_description/meshes/Chassis body.STL" />
      </geometry>
      <material
        name="">
        <color
          rgba="0.79216 0.81961 0.93333 1" />
      </material>
    </visual>
    <collision>
      <origin
        xyz="0 0 0"
        rpy="0 0 0" />
      <geometry>
        <mesh
          filename="package://segway_e1_description/meshes/Chassis body.STL" />
      </geometry>
    </collision>
  </link>
  <joint name="base_joint" type="fixed">
    <origin xyz="0 0 0" rpy="0 0 -1.57" />
    <parent link="base_link"/>
    <child link="Chassis body"/>
  </joint>

  <link
    name="Left rear wheel">
    <inertial>
      <origin
        xyz="-7.8407E-07 -2.4326E-05 0.002005"
        rpy="0 0 0" />
      <mass
        value="1.3121" />
      <inertia
        ixx="0.004883"
        ixy="-2.8757E-07"
        ixz="-1.4658E-07"
        iyy="0.0048836"
        iyz="-5.3568E-08"
        izz="0.0087354" />
    </inertial>
    <visual>
      <origin
        xyz="0 0 0"
        rpy="0 0 0" />
      <geometry>
        <mesh
          filename="package://segway_e1_description/meshes/Wheel.STL" />
      </geometry>
      <material
        name="">
        <color
          rgba="0.79216 0.81961 0.93333 1" />
      </material>
    </visual>
    <collision>
      <origin
        xyz="0 0 0"
        rpy="0 0 0" />
      <geometry>
        <mesh
          filename="package://segway_e1_description/meshes/Wheel.STL" />
      </geometry>
    </collision>
  </link>
  <joint
    name="Left_rear"
    type="continuous">
    <origin
      xyz="-0.30884 0.04815 -0.080406"
      rpy="1.5708 0 1.5708" />
    <parent
      link="Chassis body" />
    <child
      link="Left rear wheel" />
    <axis
      xyz="0 0 -1" />
  </joint>
  <link
    name="Right rear wheel">
    <inertial>
      <origin
        xyz="4.9952E-06 2.3117E-05 0.0019578"
        rpy="0 0 0" />
      <mass
        value="1.313" />
      <inertia
        ixx="0.0048865"
        ixy="3.201E-07"
        ixz="1.7545E-07"
        iyy="0.0048869"
        iyz="-2.3207E-07"
        izz="0.0087402" />
    </inertial>
    <visual>
      <origin
        xyz="0 0 0"
        rpy="0 0 0" />
      <geometry>
        <mesh
          filename="package://segway_e1_description/meshes/Wheel.STL" />
      </geometry>
      <material
        name="">
        <color
          rgba="0.79216 0.81961 0.93333 1" />
      </material>
    </visual>
    <collision>
      <origin
        xyz="0 0 0"
        rpy="0 0 0" />
      <geometry>
        <mesh
          filename="package://segway_e1_description/meshes/Wheel.STL" />
      </geometry>
    </collision>
  </link>
  <joint
    name="Right_rear"
    type="continuous">
    <origin
      xyz="0.24188 0.04815 -0.080406"
      rpy="1.5708 0 -1.5708" />
    <parent
      link="Chassis body" />
    <child
      link="Right rear wheel" />
    <axis
      xyz="0 0 -1" />
  </joint>
  <link
    name="Chassis front beam">
    <inertial>
      <origin
        xyz="-8.6161E-10 3.9501E-05 0.0062593"
        rpy="0 0 0" />
      <mass
        value="0.48416" />
      <inertia
        ixx="0.00050823"
        ixy="-1.2209E-08"
        ixz="4.3336E-11"
        iyy="0.0023652"
        iyz="2.6588E-07"
        izz="0.0023821" />
    </inertial>
    <visual>
      <origin
        xyz="0 0 0"
        rpy="0 0 0" />
      <geometry>
        <mesh
          filename="package://segway_e1_description/meshes/Chassis front beam.STL" />
      </geometry>
      <material
        name="">
        <color
          rgba="0.79216 0.81961 0.93333 1" />
      </material>
    </visual>
    <collision>
      <origin
        xyz="0 0 0"
        rpy="0 0 0" />
      <geometry>
        <mesh
          filename="package://segway_e1_description/meshes/Chassis front beam.STL" />
      </geometry>
    </collision>
  </link>
  <joint
    name="Chassis_front_joint"
    type="revolute">
    <origin
      xyz="-0.0335 0.504 -0.0515"
      rpy="0 0 0" />
    <parent
      link="Chassis body" />
    <child
      link="Chassis front beam" />
    <axis
      xyz="0 0 1" />
    <limit
      lower="-3.14"
      upper="3.14"
      effort="0"
      velocity="0" />
  </joint>
  <link
    name="Left front wheel">
    <inertial>
      <origin
        xyz="-7.0112E-05 8.4133E-05 0.54476"
        rpy="0 0 0" />
      <mass
        value="1.2504" />
      <inertia
        ixx="0.0046772"
        ixy="1.3239E-07"
        ixz="2.8374E-07"
        iyy="0.0046777"
        iyz="1.339E-07"
        izz="0.0086591" />
    </inertial>
    <visual>
      <origin
        xyz="0 0 0"
        rpy="0 0 0" />
      <geometry>
        <mesh
          filename="package://segway_e1_description/meshes/Wheel.STL" />
      </geometry>
      <material
        name="">
        <color
          rgba="0.79216 0.81961 0.93333 1" />
      </material>
    </visual>
    <collision>
      <origin
        xyz="0 0 0"
        rpy="0 0 0" />
      <geometry>
        <mesh
          filename="package://segway_e1_description/meshes/Wheel.STL" />
      </geometry>
    </collision>
  </link>
  <joint
    name="Left_front"
    type="continuous">
    <origin
      xyz="0.27184 0.0001 -0.028906"
      rpy="1.5708 0 -1.5708" />
    <parent
      link="Chassis front beam" />
    <child
      link="Left front wheel" />
    <axis
      xyz="0 0 -1" />
  </joint>
  <link
    name="Right front wheel">
    <inertial>
      <origin
        xyz="-7.0038E-05 8.4129E-05 0.54476"
        rpy="0 0 0" />
      <mass
        value="1.2504" />
      <inertia
        ixx="0.0046772"
        ixy="1.3959E-07"
        ixz="2.8223E-07"
        iyy="0.0046777"
        iyz="1.3406E-07"
        izz="0.0086591" />
    </inertial>
    <visual>
      <origin
        xyz="0 0 0"
        rpy="0 0 0" />
      <geometry>
        <mesh
          filename="package://segway_e1_description/meshes/Wheel.STL" />
      </geometry>
      <material
        name="">
        <color
          rgba="0.79216 0.81961 0.93333 1" />
      </material>
    </visual>
    <collision>
      <origin
        xyz="0 0 0"
        rpy="0 0 0" />
      <geometry>
        <mesh
          filename="package://segway_e1_description/meshes/Wheel.STL" />
      </geometry>
    </collision>
  </link>
  <joint
    name="Right_front"
    type="continuous">
    <origin
      xyz="-0.27184 0.0001 -0.028906"
      rpy="1.5708 0 1.5708" />
    <parent
      link="Chassis front beam" />
    <child
      link="Right front wheel" />
    <axis
      xyz="0 0 -1" />
  </joint>
</robot>